mplus_output/uni-06-HRS_W5.out
Mplus VERSION 8.1 (Mac)
MUTHEN & MUTHEN
04/23/2020  10:56 PM

INPUT INSTRUCTIONS

  DATA:
  FILE = "uni-06-HRS_W5.dat";

  VARIABLE:
  NAMES = mplusid UDAT UDAY UMON UYER UIWR UDWR USUB UBAK UNM1 UNM2 UNM5 UNM6;
   MISSING=.;
   CATEGORICAL ARE all; idvariable = mplusid;
  ANALYSIS:
  estimator = wlsmv; coverage=0;
  MODEL:
  g by UDAT * ;
   g by UDAY * ;
   g by UMON * ;
   g by UYER * ;
   g by UIWR * ;
   g by UDWR * ;
   g by USUB * ;
   g by UBAK * ;
   g by UNM1 * ;
   g by UNM2 * ;
   g by UNM5 * ;
   g by UNM6 * ;
   g @ 1;

  OUTPUT:
  standardized; svalues;



*** WARNING
  Data set contains cases with missing on all variables.
  These cases were not included in the analysis.
  Number of cases with missing on all variables:  743
   1 WARNING(S) FOUND IN THE INPUT INSTRUCTIONS




SUMMARY OF ANALYSIS

Number of groups                                                 1
Number of observations                                       10221

Number of dependent variables                                   12
Number of independent variables                                  0
Number of continuous latent variables                            1

Observed dependent variables

  Binary and ordered categorical (ordinal)
   UDAT        UDAY        UMON        UYER        UIWR        UDWR
   USUB        UBAK        UNM1        UNM2        UNM5        UNM6

Continuous latent variables
   G

Variables with special functions

  ID variable           MPLUSID

Estimator                                                    WLSMV
Maximum number of iterations                                  1000
Convergence criterion                                    0.500D-04
Maximum number of steepest descent iterations                   20
Maximum number of iterations for H1                           2000
Convergence criterion for H1                             0.100D-03
Parameterization                                             DELTA
Link                                                        PROBIT

Input data file(s)
  uni-06-HRS_W5.dat

Input data format  FREE


SUMMARY OF DATA

     Number of missing data patterns            63


COVARIANCE COVERAGE OF DATA

Minimum covariance coverage value   0.000


     PROPORTION OF DATA PRESENT


           Covariance Coverage
              UDAT          UDAY          UMON          UYER          UIWR
              ________      ________      ________      ________      ________
 UDAT           0.999
 UDAY           0.999         1.000
 UMON           0.999         0.999         0.999
 UYER           0.999         1.000         0.999         1.000
 UIWR           0.993         0.993         0.993         0.993         0.993
 UDWR           0.959         0.959         0.959         0.959         0.959
 USUB           0.937         0.938         0.938         0.938         0.935
 UBAK           0.991         0.991         0.991         0.991         0.987
 UNM1           0.998         0.998         0.998         0.998         0.993
 UNM2           0.984         0.984         0.984         0.984         0.979
 UNM5           0.990         0.991         0.990         0.991         0.985
 UNM6           0.949         0.949         0.949         0.949         0.944


           Covariance Coverage
              UDWR          USUB          UBAK          UNM1          UNM2
              ________      ________      ________      ________      ________
 UDWR           0.959
 USUB           0.907         0.938
 UBAK           0.954         0.936         0.992
 UNM1           0.959         0.937         0.991         0.998
 UNM2           0.946         0.927         0.977         0.984         0.984
 UNM5           0.951         0.931         0.983         0.990         0.978
 UNM6           0.912         0.895         0.943         0.948         0.941


           Covariance Coverage
              UNM5          UNM6
              ________      ________
 UNM5           0.991
 UNM6           0.947         0.949


UNIVARIATE PROPORTIONS AND COUNTS FOR CATEGORICAL VARIABLES

    UDAT
      Category 1    0.145         1481.000
      Category 2    0.855         8733.000
    UDAY
      Category 1    0.014          138.000
      Category 2    0.986        10082.000
    UMON
      Category 1    0.020          201.000
      Category 2    0.980        10012.000
    UYER
      Category 1    0.012          124.000
      Category 2    0.988        10094.000
    UIWR
      Category 1    0.000            2.000
      Category 2    0.004           44.000
      Category 3    0.012          122.000
      Category 4    0.046          468.000
      Category 5    0.111         1132.000
      Category 6    0.438         4442.000
      Category 7    0.201         2039.000
      Category 8    0.118         1194.000
      Category 9    0.051          519.000
      Category 10    0.019          191.000
    UDWR
      Category 1    0.002           19.000
      Category 2    0.023          224.000
      Category 3    0.049          477.000
      Category 4    0.104         1022.000
      Category 5    0.184         1804.000
      Category 6    0.407         3987.000
      Category 7    0.121         1186.000
      Category 8    0.064          625.000
      Category 9    0.032          317.000
      Category 10    0.014          141.000
    USUB
      Category 1    0.036          342.000
      Category 2    0.091          871.000
      Category 3    0.081          777.000
      Category 4    0.130         1249.000
      Category 5    0.194         1864.000
      Category 6    0.468         4482.000
    UBAK
      Category 1    0.033          333.000
      Category 2    0.967         9802.000
    UNM1
      Category 1    0.010           98.000
      Category 2    0.990        10106.000
    UNM2
      Category 1    0.068          681.000
      Category 2    0.932         9379.000
    UNM5
      Category 1    0.041          411.000
      Category 2    0.959         9716.000
    UNM6
      Category 1    0.226         2191.000
      Category 2    0.774         7508.000



THE MODEL ESTIMATION TERMINATED NORMALLY



MODEL FIT INFORMATION

Number of Free Parameters                       44

Chi-Square Test of Model Fit

          Value                           2832.576*
          Degrees of Freedom                    54
          P-Value                           0.0000

*   The chi-square value for MLM, MLMV, MLR, ULSMV, WLSM and WLSMV cannot be used
    for chi-square difference testing in the regular way.  MLM, MLR and WLSM
    chi-square difference testing is described on the Mplus website.  MLMV, WLSMV,
    and ULSMV difference testing is done using the DIFFTEST option.

RMSEA (Root Mean Square Error Of Approximation)

          Estimate                           0.071
          90 Percent C.I.                    0.069  0.073
          Probability RMSEA <= .05           0.000

CFI/TLI

          CFI                                0.934
          TLI                                0.920

Chi-Square Test of Model Fit for the Baseline Model

          Value                          42413.457
          Degrees of Freedom                    66
          P-Value                           0.0000

SRMR (Standardized Root Mean Square Residual)

          Value                              0.129

Optimum Function Value for Weighted Least-Squares Estimator

          Value                     0.12445108D+00



MODEL RESULTS

                                                    Two-Tailed
                    Estimate       S.E.  Est./S.E.    P-Value

 G        BY
    UDAT               0.327      0.015     21.424      0.000
    UDAY               0.424      0.035     12.184      0.000
    UMON               0.542      0.026     20.761      0.000
    UYER               0.668      0.029     23.096      0.000
    UIWR               0.879      0.007    124.157      0.000
    UDWR               0.868      0.007    122.409      0.000
    USUB               0.343      0.011     32.051      0.000
    UBAK               0.361      0.024     15.306      0.000
