mplus_output/uni-07-HRS_W7.out
Mplus VERSION 8.1 (Mac)
MUTHEN & MUTHEN
04/23/2020  10:56 PM

INPUT INSTRUCTIONS

  DATA:
  FILE = "uni-07-HRS_W7.dat";

  VARIABLE:
  NAMES = mplusid UDAT UDAY UMON UYER UIWR UDWR USUB UBAK UNM1 UNM2 UNM5 UNM6;
   MISSING=.;
   CATEGORICAL ARE all; idvariable = mplusid;
  ANALYSIS:
  estimator = wlsmv; coverage=0;
  MODEL:
  g by UDAT * ;
   g by UDAY * ;
   g by UMON * ;
   g by UYER * ;
   g by UIWR * ;
   g by UDWR * ;
   g by USUB * ;
   g by UBAK * ;
   g by UNM1 * ;
   g by UNM2 * ;
   g by UNM5 * ;
   g by UNM6 * ;
   g @ 1;

  OUTPUT:
  standardized; svalues;



*** WARNING
  Data set contains cases with missing on all variables.
  These cases were not included in the analysis.
  Number of cases with missing on all variables:  2091
   1 WARNING(S) FOUND IN THE INPUT INSTRUCTIONS




SUMMARY OF ANALYSIS

Number of groups                                                 1
Number of observations                                       17489

Number of dependent variables                                   12
Number of independent variables                                  0
Number of continuous latent variables                            1

Observed dependent variables

  Binary and ordered categorical (ordinal)
   UDAT        UDAY        UMON        UYER        UIWR        UDWR
   USUB        UBAK        UNM1        UNM2        UNM5        UNM6

Continuous latent variables
   G

Variables with special functions

  ID variable           MPLUSID

Estimator                                                    WLSMV
Maximum number of iterations                                  1000
Convergence criterion                                    0.500D-04
Maximum number of steepest descent iterations                   20
Maximum number of iterations for H1                           2000
Convergence criterion for H1                             0.100D-03
Parameterization                                             DELTA
Link                                                        PROBIT

Input data file(s)
  uni-07-HRS_W7.dat

Input data format  FREE


SUMMARY OF DATA

     Number of missing data patterns           115


COVARIANCE COVERAGE OF DATA

Minimum covariance coverage value   0.000


     PROPORTION OF DATA PRESENT


           Covariance Coverage
              UDAT          UDAY          UMON          UYER          UIWR
              ________      ________      ________      ________      ________
 UDAT           0.542
 UDAY           0.542         0.542
 UMON           0.541         0.541         0.542
 UYER           0.541         0.542         0.541         0.542
 UIWR           0.528         0.528         0.528         0.528         0.984
 UDWR           0.483         0.483         0.483         0.483         0.928
 USUB           0.490         0.490         0.490         0.490         0.913
 UBAK           0.534         0.534         0.534         0.534         0.978
 UNM1           0.540         0.541         0.540         0.541         0.528
 UNM2           0.523         0.524         0.523         0.524         0.513
 UNM5           0.534         0.535         0.535         0.535         0.523
 UNM6           0.524         0.525         0.524         0.525         0.513


           Covariance Coverage
              UDWR          USUB          UBAK          UNM1          UNM2
              ________      ________      ________      ________      ________
 UDWR           0.928
 USUB           0.869         0.921
 UBAK           0.923         0.918         0.990
 UNM1           0.483         0.490         0.534         0.541
 UNM2           0.472         0.479         0.518         0.524         0.524
 UNM5           0.480         0.487         0.528         0.535         0.520
 UNM6           0.471         0.481         0.519         0.524         0.511


           Covariance Coverage
              UNM5          UNM6
              ________      ________
 UNM5           0.535
 UNM6           0.523         0.525


UNIVARIATE PROPORTIONS AND COUNTS FOR CATEGORICAL VARIABLES

    UDAT
      Category 1    0.177         1679.000
      Category 2    0.823         7798.000
    UDAY
      Category 1    0.031          294.000
      Category 2    0.969         9189.000
    UMON
      Category 1    0.028          268.000
      Category 2    0.972         9203.000
    UYER
      Category 1    0.023          214.000
      Category 2    0.977         9270.000
    UIWR
      Category 1    0.001           11.000
      Category 2    0.010          166.000
      Category 3    0.031          525.000
      Category 4    0.083         1426.000
      Category 5    0.155         2673.000
      Category 6    0.438         7529.000
      Category 7    0.155         2660.000
      Category 8    0.084         1453.000
      Category 9    0.033          562.000
      Category 10    0.012          199.000
    UDWR
      Category 1    0.003           49.000
      Category 2    0.040          651.000
      Category 3    0.075         1223.000
      Category 4    0.139         2262.000
      Category 5    0.207         3362.000
      Category 6    0.368         5972.000
      Category 7    0.089         1452.000
      Category 8    0.047          756.000
      Category 9    0.021          338.000
      Category 10    0.010          160.000
    USUB
      Category 1    0.033          527.000
      Category 2    0.109         1750.000
      Category 3    0.089         1430.000
      Category 4    0.122         1962.000
      Category 5    0.189         3047.000
      Category 6    0.459         7386.000
    UBAK
      Category 1    0.044          760.000
      Category 2    0.956        16551.000
    UNM1
      Category 1    0.007           66.000
      Category 2    0.993         9403.000
    UNM2
      Category 1    0.069          629.000
      Category 2    0.931         8541.000
    UNM5
      Category 1    0.040          371.000
      Category 2    0.960         8992.000
    UNM6
      Category 1    0.070          644.000
      Category 2    0.930         8540.000



THE MODEL ESTIMATION TERMINATED NORMALLY



MODEL FIT INFORMATION

Number of Free Parameters                       44

Chi-Square Test of Model Fit

          Value                           3267.739*
          Degrees of Freedom                    54
          P-Value                           0.0000

*   The chi-square value for MLM, MLMV, MLR, ULSMV, WLSM and WLSMV cannot be used
    for chi-square difference testing in the regular way.  MLM, MLR and WLSM
    chi-square difference testing is described on the Mplus website.  MLMV, WLSMV,
    and ULSMV difference testing is done using the DIFFTEST option.

RMSEA (Root Mean Square Error Of Approximation)

          Estimate                           0.058
          90 Percent C.I.                    0.057  0.060
          Probability RMSEA <= .05           0.000

CFI/TLI

          CFI                                0.963
          TLI                                0.955

Chi-Square Test of Model Fit for the Baseline Model

          Value                          86873.337
          Degrees of Freedom                    66
          P-Value                           0.0000

SRMR (Standardized Root Mean Square Residual)

          Value                              0.133

Optimum Function Value for Weighted Least-Squares Estimator

          Value                     0.85891521D-01



MODEL RESULTS

                                                    Two-Tailed
                    Estimate       S.E.  Est./S.E.    P-Value

 G        BY
    UDAT               0.432      0.013     32.760      0.000
    UDAY               0.655      0.020     32.759      0.000
    UMON               0.728      0.020     36.771      0.000
    UYER               0.881      0.018     49.508      0.000
    UIWR               0.889      0.007    124.638      0.000
    UDWR               0.883      0.007    119.542      0.000
    USUB               0.337      0.008     40.477      0.000
